Traceback (most recent call last):
  File "O:\Projects\TGbot\Workers.py", line 22, in <module>
    sheetHandler.delete_row(SHEET_UID, 4, 4)
  File "O:\Projects\TGbot\Services\Interfaces\GoogleSheets.py", line 96, in delete_row
    ).execute()
      ^^^^^^^^^
  File "O:\Projects\TGbot\venv\Lib\site-packages\googleapiclient\_helpers.py", line 130, in positional_wrapper
    return wrapped(*args, **kwargs)
           ^^^^^^^^^^^^^^^^^^^^^^^^
  File "O:\Projects\TGbot\venv\Lib\site-packages\googleapiclient\http.py", line 938, in execute
    raise HttpError(resp, content, uri=self.uri)
googleapiclient.errors.HttpError: <HttpError 400 when requesting https://sheets.googleapis.com/v4/spreadsheets/1cbPYocbpmCPqLB-oQByNv1sv9aQHl5lNrjbruRfzF_A:batchUpdate?alt=json returned "Invalid value at 'requests[0].delete_dimension.range.sheet_id' (TYPE_INT32), "1cbPYocbpmCPqLB-oQByNv1sv9aQHl5lNrjbruRfzF_A"". Details: "[{'@type': 'type.googleapis.com/google.rpc.BadRequest', 'fieldViolations': [{'field': 'requests[0].delete_dimension.range.sheet_id', 'description': 'Invalid value at \'requests[0].delete_dimension.range.sheet_id\' (TYPE_INT32), "1cbPYocbpmCPqLB-oQByNv1sv9aQHl5lNrjbruRfzF_A"'}]}]">
